<?xml version="1.0"?>
<robot name="piklet_bot">
  
  <!-- World Link (dummy link to avoid KDL warning) -->
  <link name="world"/>
  
  <!-- Base Link -->
  <link name="base_link">
    <visual>
      <geometry>
        <mesh filename="package://piklet_description/urdf/meshes/base.dae"/>
      </geometry>
      <material name="base_material">
        <color rgba="0.8 0.8 0.8 1.0"/>
      </material>
    </visual>
    <collision>
      <geometry>
        <box size="0.3 0.3 0.1"/>
      </geometry>
    </collision>
    <inertial>
      <mass value="5.0"/>
      <inertia ixx="0.1" ixy="0.0" ixz="0.0" iyy="0.1" iyz="0.0" izz="0.1"/>
    </inertial>
  </link>
  
  <!-- World to Base Joint -->
  <joint name="world_to_base" type="fixed">
    <parent link="world"/>
    <child link="base_link"/>
    <origin xyz="0 0 0" rpy="0 0 0"/>
  </joint>
  
  <!-- Arm Link -->
  <link name="arm_link">
    <visual>
      <geometry>
        <mesh filename="package://piklet_description/urdf/meshes/arm.dae"/>
      </geometry>
      <material name="arm_material">
        <color rgba="0.2 0.2 0.8 1.0"/>
      </material>
    </visual>
    <collision>
      <geometry>
        <cylinder radius="0.05" length="0.4"/>
      </geometry>
    </collision>
    <inertial>
      <mass value="2.0"/>
      <inertia ixx="0.05" ixy="0.0" ixz="0.0" iyy="0.05" iyz="0.0" izz="0.01"/>
    </inertial>
  </link>
  
  <!-- Gripper Link -->
  <link name="gripper_link">
    <visual>
      <geometry>
        <mesh filename="package://piklet_description/urdf/meshes/gripper.dae"/>
      </geometry>
      <material name="gripper_material">
        <color rgba="0.8 0.2 0.2 1.0"/>
      </material>
    </visual>
    <collision>
      <geometry>
        <box size="0.1 0.05 0.05"/>
      </geometry>
    </collision>
    <inertial>
      <mass value="0.5"/>
      <inertia ixx="0.01" ixy="0.0" ixz="0.0" iyy="0.01" iyz="0.0" izz="0.01"/>
    </inertial>
  </link>
  
  <!-- Base to Arm Joint -->
  <joint name="base_to_arm" type="revolute">
    <parent link="base_link"/>
    <child link="arm_link"/>
    <origin xyz="0 0 0.15" rpy="0 0 0"/>
    <axis xyz="0 0 1"/>
    <limit lower="-1.57" upper="1.57" effort="10" velocity="1"/>
  </joint>
  
  <!-- Arm to Gripper Joint -->
  <joint name="arm_to_gripper" type="revolute">
    <parent link="arm_link"/>
    <child link="gripper_link"/>
    <origin xyz="0 0 0.25" rpy="0 0 0"/>
    <axis xyz="0 0 1"/>
    <limit lower="-1.57" upper="1.57" effort="10" velocity="1"/>
  </joint>
  
</robot>