<?xml version="1.0" ?>
<!-- =================================================================================== -->
<!-- |    This document was autogenerated by xacro from /home/gp/piklet/piklet_ws/install/piklet_description/share/piklet_description/urdf/piklet_robot.urdf.xacro | -->
<!-- |    EDITING THIS FILE BY HAND IS NOT RECOMMENDED                                 | -->
<!-- =================================================================================== -->
<robot name="piklet_container_bot" xmlns:gazebo="http://gazebosim.org/" xmlns:ros="http://www.ros.org/wiki/ros">
  <material name="gray">
    <color rgba="0.6 0.6 0.6 1"/>
  </material>
  <material name="blue">
    <color rgba="0.2 0.4 0.8 1"/>
  </material>
  <material name="black">
    <color rgba="0 0 0 1"/>
  </material>
  <material name="darkgray">
    <color rgba="0.3 0.3 0.3 1"/>
  </material>
  <material name="red">
    <color rgba="0.8 0.1 0.1 1"/>
  </material>
  <material name="yellow">
    <color rgba="0.5 0.3 0.1 1"/>
  </material>
  <material name="green">
    <color rgba="0.2 0.8 0.2 1"/>
  </material>
  <material name="white">
    <color rgba="1 1 1 1"/>
  </material>
  <!-- front mount -->
  <link name="front_mount">
    <inertial>
      <mass value="0.3"/>
      <origin xyz="0 0 0"/>
      <inertia ixx="0.0010675" ixy="0" ixz="0" iyy="0.0010675" iyz="0" izz="0.0010675"/>
    </inertial>
    <visual>
      <geometry>
        <cylinder length="0.2" radius="0.03"/>
      </geometry>
      <origin rpy="0 0 0" xyz="0 0 0"/>
      <material name="blue"/>
    </visual>
    <collision>
      <geometry>
        <cylinder length="0.2" radius="0.03"/>
      </geometry>
      <origin rpy="0 0 0" xyz="0 0 0"/>
    </collision>
  </link>
  <joint name="front_mount_joint" type="fixed">
    <parent link="base_top"/>
    <child link="front_mount"/>
    <origin rpy="0 0 0" xyz="0.13 0 0.09"/>
  </joint>
  <!-- Bottom plate -->
  <link name="base_link">
    <inertial>
      <mass value="5"/>
      <origin xyz="0 0 0"/>
      <inertia ixx="0.02829166666666666" ixy="0" ixz="0" iyy="0.02829166666666666" iyz="0" izz="0.02829166666666666"/>
    </inertial>
    <visual>
      <origin rpy="0 0 0" xyz="0 0 0"/>
      <geometry>
        <cylinder length="0.02" radius="0.15"/>
      </geometry>
      <material name="white"/>
    </visual>
    <collision>
      <origin rpy="0 0 0" xyz="0 0 0"/>
      <geometry>
        <cylinder length="0.02" radius="0.15"/>
      </geometry>
    </collision>
  </link>
  <!-- Top plate -->
  <link name="base_top">
    <inertial>
      <mass value="5"/>
      <origin xyz="0 0 0"/>
      <inertia ixx="0.02829166666666666" ixy="0" ixz="0" iyy="0.02829166666666666" iyz="0" izz="0.02829166666666666"/>
    </inertial>
    <visual>
      <origin rpy="0 0 0" xyz="0 0 0"/>
      <geometry>
        <cylinder length="0.02" radius="0.15"/>
      </geometry>
      <material name="white"/>
    </visual>
    <collision>
      <origin rpy="0 0 0" xyz="0 0 0"/>
      <geometry>
        <cylinder length="0.02" radius="0.15"/>
      </geometry>
    </collision>
  </link>
  <joint name="base_top_joint" type="fixed">
    <origin xyz="0 0 0.2"/>
    <parent link="base_link"/>
    <child link="base_top"/>
  </joint>
  <link name="pole_fl">
    <visual>
      <geometry>
        <cylinder length="0.2" radius="0.01"/>
      </geometry>
      <material name="darkgray"/>
    </visual>
  </link>
  <joint name="pole_fl_joint" type="fixed">
    <origin rpy="0 0 0" xyz="0.1 0.1 0.1"/>
    <parent link="base_link"/>
    <child link="pole_fl"/>
  </joint>
  <link name="pole_fr">
    <visual>
      <geometry>
        <cylinder length="0.2" radius="0.01"/>
      </geometry>
      <material name="darkgray"/>
    </visual>
  </link>
  <joint name="pole_fr_joint" type="fixed">
    <origin rpy="0 0 0" xyz="0.1 -0.1 0.1"/>
    <parent link="base_link"/>
    <child link="pole_fr"/>
  </joint>
  <link name="pole_bl">
    <visual>
      <geometry>
        <cylinder length="0.2" radius="0.01"/>
      </geometry>
      <material name="darkgray"/>
    </visual>
  </link>
  <joint name="pole_bl_joint" type="fixed">
    <origin rpy="0 0 0" xyz="-0.1 0.1 0.1"/>
    <parent link="base_link"/>
    <child link="pole_bl"/>
  </joint>
  <link name="pole_br">
    <visual>
      <geometry>
        <cylinder length="0.2" radius="0.01"/>
      </geometry>
      <material name="darkgray"/>
    </visual>
  </link>
  <joint name="pole_br_joint" type="fixed">
    <origin rpy="0 0 0" xyz="-0.1 -0.1 0.1"/>
    <parent link="base_link"/>
    <child link="pole_br"/>
  </joint>
  <link name="right_wheel">
    <visual>
      <origin rpy="1.5707963267948966 0 0" xyz="0 0 0"/>
      <geometry>
        <cylinder length="0.02" radius="0.039"/>
      </geometry>
      <material name="black"/>
    </visual>
    <collision>
      <origin rpy="1.5707963267948966 0 0 " xyz="0 0 0"/>
      <geometry>
        <cylinder length="0.02" radius="0.039"/>
      </geometry>
      <surface>
        <friction>
          <ode>
            <mu>1.0</mu>
            <mu2>1.0</mu2>
          </ode>
        </friction>
      </surface>
    </collision>
    <inertial>
      <mass value="2.5"/>
      <origin xyz="0 0 0"/>
      <inertia ixx="0.001" ixy="0.0" ixz="0.0" iyy="0.001" iyz="0.0" izz="0.001"/>
    </inertial>
  </link>
  <joint name="right_wheel_joint" type="continuous">
    <parent link="base_link"/>
    <child link="right_wheel"/>
    <origin rpy="0 0 0" xyz="0 -0.15 0"/>
    <axis rpy="0 0 0" xyz="0 1 0"/>
    <limit effort="100" velocity="100"/>
    <dynamics damping="0.5" friction="0.2"/>
  </joint>
  <link name="left_wheel">
    <visual>
      <origin rpy="1.5707963267948966 0 0" xyz="0 0 0"/>
      <geometry>
        <cylinder length="0.02" radius="0.039"/>
      </geometry>
      <material name="black"/>
    </visual>
    <collision>
      <origin rpy="1.5707963267948966 0 0 " xyz="0 0 0"/>
      <geometry>
        <cylinder length="0.02" radius="0.039"/>
      </geometry>
      <surface>
        <friction>
          <ode>
            <mu>1.0</mu>
            <mu2>1.0</mu2>
          </ode>
        </friction>
      </surface>
    </collision>
    <inertial>
      <mass value="2.5"/>
      <origin xyz="0 0 0"/>
      <inertia ixx="0.001" ixy="0.0" ixz="0.0" iyy="0.001" iyz="0.0" izz="0.001"/>
    </inertial>
  </link>
  <joint name="left_wheel_joint" type="continuous">
    <parent link="base_link"/>
    <child link="left_wheel"/>
    <origin rpy="0 0 0" xyz="0 0.15 0"/>
    <axis rpy="0 0 0" xyz="0 1 0"/>
    <limit effort="100" velocity="100"/>
    <dynamics damping="0.5" friction="0.2"/>
  </joint>
  <joint name="passive_wheel_front_joint" type="fixed">
    <parent link="base_link"/>
    <child link="passive_wheel_front_link"/>
    <origin rpy="-1.5707963267948966 0 0" xyz="0.115 0.0 0.007"/>
  </joint>
  <link name="passive_wheel_front_link">
    <visual>
      <origin rpy="1.5707963267948966 0 0" xyz="0 0.02 0"/>
      <geometry>
        <sphere radius="0.025"/>
      </geometry>
      <material name="black"/>
    </visual>
    <collision>
      <geometry>
        <sphere radius="0.025"/>
      </geometry>
      <origin rpy="1.5707963267948966 0 0" xyz="0 0.02 0"/>
    </collision>
    <inertial>
      <mass value="0.5"/>
      <origin xyz="0 0 0"/>
      <inertia ixx="0.001" ixy="0.0" ixz="0.0" iyy="0.001" iyz="0.0" izz="0.001"/>
    </inertial>
  </link>
  <joint name="passive_wheel_back_joint" type="fixed">
    <parent link="base_link"/>
    <child link="passive_wheel_back_link"/>
    <origin rpy="-1.5707963267948966 0 0" xyz="-0.135 0.0 0.009"/>
  </joint>
  <link name="passive_wheel_back_link">
    <visual>
      <origin rpy="1.5707963267948966 0 0" xyz="0.02 0.02 0 "/>
      <geometry>
        <sphere radius="0.025"/>
      </geometry>
      <material name="black"/>
    </visual>
    <collision>
      <geometry>
        <sphere radius="0.025"/>
      </geometry>
      <origin rpy="1.5707963267948966 0 0" xyz="0 0.02 0"/>
    </collision>
    <inertial>
      <mass value="0.5"/>
      <origin xyz="0 0 0"/>
      <inertia ixx="0.001" ixy="0.0" ixz="0.0" iyy="0.001" iyz="0.0" izz="0.001"/>
    </inertial>
  </link>
  <link name="shoulder_yaw_link">
    <inertial>
      <mass value="1e-6"/>
      <inertia ixx="1e-9" ixy="0" ixz="0" iyy="1e-9" iyz="0" izz="1e-9"/>
    </inertial>
  </link>
  <joint name="shoulder_yaw" type="revolute">
    <parent link="front_mount"/>
    <child link="shoulder_yaw_link"/>
    <origin rpy="0 0 0" xyz="0 0 -0.05"/>
    <axis xyz="0 0 1"/>
    <limit effort="5" lower="-1.57" upper="1.57" velocity="1"/>
  </joint>
  <link name="shoulder_pitch_link">
    <inertial>
      <mass value="1e-6"/>
      <inertia ixx="1e-9" ixy="0" ixz="0" iyy="1e-9" iyz="0" izz="1e-9"/>
    </inertial>
  </link>
  <joint name="shoulder_pitch" type="revolute">
    <parent link="shoulder_yaw_link"/>
    <child link="shoulder_pitch_link"/>
    <origin rpy="0 0 0" xyz="0 0 0"/>
    <axis xyz="0 1 0"/>
    <limit effort="5" lower="-1.57" upper="1.57" velocity="1"/>
  </joint>
  <link name="shoulder_roll_link">
    <inertial>
      <mass value="1e-6"/>
      <inertia ixx="1e-9" ixy="0" ixz="0" iyy="1e-9" iyz="0" izz="1e-9"/>
    </inertial>
  </link>
  <joint name="shoulder_roll" type="revolute">
    <parent link="shoulder_pitch_link"/>
    <child link="shoulder_roll_link"/>
    <origin rpy="0 0 0" xyz="0 0 0"/>
    <axis xyz="1 0 0"/>
    <limit effort="5" lower="-1.57" upper="1.57" velocity="1"/>
  </joint>
  <link name="arm_link1">
    <inertial>
      <mass value="0.4"/>
      <inertia ixx="5.06e-4" ixy="0" ixz="0" iyy="5.06e-4" iyz="0" izz="1.25e-4"/>
    </inertial>
    <visual>
      <geometry>
        <cylinder length="0.16" radius="0.025"/>
      </geometry>
      <origin rpy="0 1.5707963267948966 0" xyz="0.08 0 0"/>
      <material name="green"/>
    </visual>
    <collision>
      <geometry>
        <cylinder length="0.16" radius="0.025"/>
      </geometry>
      <origin rpy="0 1.5707963267948966 0" xyz="0.08 0 0"/>
    </collision>
  </link>
  <joint name="arm_link1_joint" type="fixed">
    <parent link="shoulder_roll_link"/>
    <child link="arm_link1"/>
    <origin rpy="0 0 0" xyz="0 0 0"/>
  </joint>
  <link name="arm_link2">
    <inertial>
      <mass value="0.25"/>
      <inertia ixx="5e-4" ixy="0" ixz="0" iyy="5e-4" iyz="0" izz="2e-4"/>
    </inertial>
    <visual>
      <geometry>
        <cylinder length="0.12" radius="0.02"/>
      </geometry>
      <origin rpy="0 1.5707963267948966 0" xyz="0.06 0 0"/>
      <material name="yellow"/>
    </visual>
    <collision>
      <geometry>
        <cylinder length="0.12" radius="0.02"/>
      </geometry>
      <origin rpy="0 1.5707963267948966 0" xyz="0.06 0 0"/>
    </collision>
  </link>
  <joint name="elbow_joint" type="revolute">
    <parent link="arm_link1"/>
    <child link="arm_link2"/>
    <origin rpy="0 0 0" xyz="0.16 0 0"/>
    <axis xyz="0 1 0"/>
    <limit effort="5" lower="-1.57" upper="1.57" velocity="1"/>
  </joint>
  <link name="arm_link_end">
    <inertial>
      <mass value="0.15"/>
      <inertia ixx="2e-4" ixy="0" ixz="0" iyy="2e-4" iyz="0" izz="1e-4"/>
    </inertial>
    <visual>
      <geometry>
        <cylinder length="0.08" radius="0.015"/>
      </geometry>
      <origin rpy="0 1.5707963267948966 0" xyz="0.04 0 0"/>
      <material name="red"/>
    </visual>
    <collision>
      <geometry>
        <cylinder length="0.08" radius="0.015"/>
      </geometry>
      <origin rpy="0 1.5707963267948966 0" xyz="0.04 0 0"/>
    </collision>
  </link>
  <joint name="wrist_joint" type="revolute">
    <parent link="arm_link2"/>
    <child link="arm_link_end"/>
    <origin rpy="0 0 0" xyz="0.12 0 0"/>
    <axis xyz="0 1 0"/>
    <limit effort="5" lower="-1.57" upper="1.57" velocity="1"/>
  </joint>
  <!-- Base link for the gripper -->
  <link name="gripper_base">
    <visual>
      <geometry>
        <box size="0.05 0.02 0.02"/>
        <!-- small gripper base block -->
      </geometry>
      <material name="gray">
        <color rgba="0.5 0.5 0.5 1"/>
      </material>
    </visual>
    <collision>
      <geometry>
        <box size="0.05 0.02 0.02"/>
      </geometry>
    </collision>
    <inertial>
      <mass value="0.1"/>
      <origin xyz="0 0 0"/>
      <inertia ixx="1e-4" ixy="0" ixz="0" iyy="1e-4" iyz="0" izz="1e-4"/>
    </inertial>
  </link>
  <!-- Attach base to parent arm link -->
  <joint name="gripper_mount_joint" type="fixed">
    <parent link="arm_link_end"/>
    <child link="gripper_base"/>
    <origin rpy="3.14 0 0" xyz="0.1 0 0"/>
  </joint>
  <!-- Left finger -->
  <link name="gripper_left_finger">
    <visual>
      <geometry>
        <box size="0.02 0.01 0.06"/>
      </geometry>
      <origin rpy="0 0 0" xyz="0 0 0.03"/>
      <material name="dark_gray">
        <color rgba="0.3 0.3 0.3 1"/>
      </material>
    </visual>
    <collision>
      <geometry>
        <box size="0.02 0.01 0.06"/>
      </geometry>
      <origin rpy="0 0 0" xyz="0 0 0.03"/>
    </collision>
    <inertial>
      <mass value="0.05"/>
      <origin xyz="0 0 0.03"/>
      <inertia ixx="5e-5" ixy="0" ixz="0" iyy="5e-5" iyz="0" izz="5e-5"/>
    </inertial>
  </link>
  <!-- Concave tip (approximated with a small cylinder) -->
  <link name="gripper_left_tip">
    <visual>
      <geometry>
        <cylinder length="0.01" radius="0.01"/>
      </geometry>
      <origin rpy="1.57 0 0" xyz="0 0 0.06"/>
      <!-- rotate so it's a "cup" -->
      <material name="rubber">
        <color rgba="0.1 0.1 0.1 1"/>
      </material>
    </visual>
    <collision>
      <geometry>
        <cylinder length="0.01" radius="0.01"/>
      </geometry>
      <origin rpy="1.57 0 0" xyz="0 0 0.06"/>
    </collision>
    <inertial>
      <mass value="0.01"/>
      <origin xyz="0 0 0.06"/>
      <inertia ixx="1e-5" ixy="0" ixz="0" iyy="1e-5" iyz="0" izz="1e-5"/>
    </inertial>
  </link>
  <joint name="gripper_left_joint" type="prismatic">
    <parent link="gripper_base"/>
    <child link="gripper_left_finger"/>
    <origin rpy="0 0 0" xyz="0 0.015 0"/>
    <axis xyz="0 -1 0"/>
    <limit effort="10" lower="0.0" upper="0.04" velocity="0.02"/>
  </joint>
  <joint name="gripper_left_tip_joint" type="fixed">
    <parent link="gripper_left_finger"/>
    <child link="gripper_left_tip"/>
    <origin xyz="0 0 0"/>
  </joint>
  <!-- Right finger -->
  <link name="gripper_right_finger">
    <visual>
      <geometry>
        <box size="0.02 0.01 0.06"/>
      </geometry>
      <origin xyz="0 0 0.03"/>
      <material name="dark_gray"/>
    </visual>
    <collision>
      <geometry>
        <box size="0.02 0.01 0.06"/>
      </geometry>
      <origin xyz="0 0 0.03"/>
    </collision>
    <inertial>
      <mass value="0.05"/>
      <origin xyz="0 0 0.03"/>
      <inertia ixx="5e-5" ixy="0" ixz="0" iyy="5e-5" iyz="0" izz="5e-5"/>
    </inertial>
  </link>
  <link name="gripper_right_tip">
    <visual>
      <geometry>
        <cylinder length="0.01" radius="0.01"/>
      </geometry>
      <origin rpy="1.57 0 0" xyz="0 0 0.06"/>
      <material name="rubber"/>
    </visual>
    <collision>
      <geometry>
        <cylinder length="0.01" radius="0.01"/>
      </geometry>
      <origin rpy="1.57 0 0" xyz="0 0 0.06"/>
    </collision>
    <inertial>
      <mass value="0.01"/>
      <origin xyz="0 0 0.06"/>
      <inertia ixx="1e-5" ixy="0" ixz="0" iyy="1e-5" iyz="0" izz="1e-5"/>
    </inertial>
  </link>
  <joint name="gripper_right_joint" type="prismatic">
    <parent link="gripper_base"/>
    <child link="gripper_right_finger"/>
    <origin rpy="0 0 0" xyz="0 -0.015 0"/>
    <axis xyz="0 1 0"/>
    <limit effort="10" lower="0.0" upper="0.04" velocity="0.02"/>
    <!-- Mimic left finger for symmetry -->
    <mimic joint="gripper_left_joint" multiplier="1" offset="0"/>
  </joint>
  <joint name="gripper_right_tip_joint" type="fixed">
    <parent link="gripper_right_finger"/>
    <child link="gripper_right_tip"/>
  </joint>
  <!-- Define TCP (tool center point) -->
  <link name="gripper_tool"/>
  <joint name="gripper_tool_joint" type="fixed">
    <parent link="gripper_base"/>
    <child link="gripper_tool"/>
    <origin rpy="0 0 0" xyz="0.1 0 0"/>
  </joint>
  <link name="lidar_link">
    <visual>
      <geometry>
        <cylinder length="0.05" radius="0.04"/>
      </geometry>
      <origin xyz="0 0 0"/>
      <material name="red"/>
    </visual>
    <collision>
      <origin rpy="0 0 0" xyz="0 0 0"/>
      <geometry>
        <cylinder length="0.05" radius="0.04"/>
      </geometry>
    </collision>
  </link>
  <joint name="lidar_joint" type="fixed">
    <origin xyz="0 0 0.030"/>
    <parent link="base_top"/>
    <child link="lidar_link"/>
  </joint>
  <link name="depth_camera_link">
    <visual>
      <geometry>
        <box size="0.06 0.04 0.04"/>
      </geometry>
      <material name="green"/>
    </visual>
    <collision>
      <origin rpy="0 0 0" xyz="0 0 0"/>
      <geometry>
        <box size="0.06 0.04 0.04"/>
      </geometry>
    </collision>
  </link>
  <joint name="depth_camera_mount" type="fixed">
    <parent link="front_mount"/>
    <child link="depth_camera_link"/>
    <origin xyz="0 0 0.12"/>
  </joint>
  <gazebo>
    <plugin filename="gz-sim-diff-drive-system" name="gz::sim::systems::DiffDrive">
      <!-- wheels -->
      <left_joint>left_wheel_joint</left_joint>
      <right_joint>right_wheel_joint</right_joint>
      <!-- physics -->
      <wheel_separation>0.34</wheel_separation>
      <wheel_radius>0.05</wheel_radius>
      <max_wheel_torque>10.0</max_wheel_torque>
      <max_wheel_acceleration>5.0</max_wheel_acceleration>
      <!-- odom frame -->
      <odom_frame>odom</odom_frame>
      <base_frame>base_link</base_frame>
      <publish_odom>true</publish_odom>
      <!-- topic interface -->
      <topic>cmd_vel</topic>
      <!-- stop wheels if no command received -->
      <command_timeout>0.5</command_timeout>
      <!-- seconds -->
    </plugin>
    <plugin filename="gz-sim-joint-state-publisher-system" name="gz::sim::systems::JointStatePublisher">
      <topic>joint_states</topic>
      <joint_name>right_wheel_joint</joint_name>
      <joint_name>left_wheel_joint</joint_name>
    </plugin>
  </gazebo>
  <!--xacro:lidar_plugin parent="lidar_link"/-->
  <!--xacro:depth_camera_plugin parent="depth_camera_link"/-->
</robot>
