<?xml version="1.0"?>
<robot xmlns:xacro="http://www.ros.org/wiki/xacro">

  <xacro:macro name="wheel" params="side parent translateX translateY">
    <link name="${side}_wheel">
      <visual>
        <origin xyz="0 0 0" rpy="${M_PI/2} 0 0" />
        <geometry>
          <cylinder length="${wheel_height}" radius="${wheel_radius}" />
        </geometry>
        <material name="black" />
      </visual>
      <collision>
        <origin xyz="0 0 0" rpy="${M_PI/2} 0 0 " />
        <geometry>
          <cylinder length="${wheel_height}" radius="${wheel_radius}" />
        </geometry>
      </collision>
      <inertial>
        <mass value="${wheel_mass}" />
        <origin xyz="0 0 0" />
        <inertia ixx="0.001" ixy="0.0" ixz="0.0"
          iyy="0.001" iyz="0.0"
          izz="0.001" />
      </inertial>
    </link>
    <joint name="${side}_wheel_joint" type="continuous">
      <parent link="${parent}" />
      <child link="${side}_wheel" />
      <origin xyz="0 ${translateY} 0" rpy="0 0 0" />
      <axis xyz="0 1 0" rpy="0 0 0" />
      <limit effort="100" velocity="100" />
      <joint_properties damping="0.0" friction="0.0" />
    </joint>
  </xacro:macro>


  <xacro:macro name="drive_wheel" params="name parent xyz">
    <link name="${name}">
      <visual>
        <geometry><cylinder radius="0.05" length="0.02"/></geometry>
        <origin rpy="0 1.57 0"/>
        <material name="black"/>
      </visual>
    </link>
    <joint name="${name}_joint" type="continuous">
      <origin xyz="${xyz}" rpy="0 1.57 0"/>
      <parent link="${parent}"/>
      <child link="${name}"/>
      <axis xyz="0 0 1"/>
    </joint>
  </xacro:macro>

</robot>
